Workbook

Sheet Mode d'emploi
A1: Référentiel d'auto-évaluation BPP — SFPO
A2: Fichier maître : c'est ce fichier que l'outil importe. Toute évolution du questionnaire se fait ici.
A4: Version du référentiel | B4: 2026-10-08
A5: « Ancien code » se rapporte à la version | B5: 2026-10-07
A7: Feuille « Référentiel » | B7: Une ligne par titre ou par question, dans l'ordre d'affichage.
A8: Type | B8: Titre (chapitre / section) · Question (reçoit une réponse) · Intitulé commun (début de phrase partagé par ses sous-questions, sans réponse).
A9: Niveau | B9: Titres uniquement : 1 = chapitre (menu latéral), 2 = section, 3 à 5 = sous-sections.
A10: Code | B10: Unique. Format Q123, sous-question Q123.01, sous-sous-question Q123.01.02 (séparateur point).
A11: Ancien code | B11: À remplir si vous renumérotez ou fusionnez des questions : code(s) précédent(s), séparés par une virgule. Les réponses déjà saisies suivent ainsi la question. Laisser vide sinon.
A12: Question chapeau | B12: Rempli d'après le code (Q123.01 → Q123). Doit exister.
A13: Condition | B13: Question à laquelle il faut répondre (colonne G) et réponse attendue OUI ou NON (colonne H) pour afficher la question. « OUI » inclut « partiellement ».
A14: Réf. BPP | B14: Toutes les références, séparées par « , ». Chaque référence doit figurer dans la feuille « Références BPP ».
A15: Contrôle | B15: Calculé : doit valoir OK sur chaque question avant de transmettre le fichier.
A16: Sévérité | B16: Questions uniquement : Critique, Majeur ou Mineur (colonne M), impact potentiel d'un écart sur le patient, le personnel ou le produit ; colonne N : motif. Sert au verdict de l'onglet « Avis d'expert » et au rapport d'audit. Synthèse dans la feuille « Sévérités ».
... A24: Avant chaque nouvelle version | B24: 1) Changer « Version du référentiel » (ex. date du jour) ; 2) recopier l'ancienne version dans « « Ancien code » se rapporte à la version » ; 3) vider la colonne « Ancien code », puis ne la remplir que pour les questions renumérotées ou fusionnées. L'import refuse un fichier dont la version de référence ne correspond pas à celle en service.

Sheet Référentiel
A1: Ordre | B1: Type | C1: Niveau | D1: Code | E1: Ancien code | F1: Question chapeau | G1: Condition : question | H1: Condition : réponse | I1: Intitulé | J1: Réf. BPP | K1: Contrôle | L1: aide (masquée) | M1: Sévérité | N1: Motif de la sévérité
A2: 1 | B2: Titre | C2: 1 | I2: MANAGEMENT DU SYSTÈME QUALITÉ PHARMACEUTIQUE
A3: 2 | B3: Titre | C3: 2 | I3: PRINCIPES
A4: 3 | B4: Question | D4: Q001 | E4: S 01 | I4: Les préparations pharmaceutiques réalisées garantissent une qualité constante, appropriée à leur usage, conformément aux exigences des BPP | J4: 1.01 | K4: =IF(COUNTIF($D$2:$D$2000,D4)>1,"Code en double",IF(AND(F4<>"",COUNTIF($D$2:$D$2000,F4)=0),"Question chapeau inconnue",IF(AND(G4<>"",COUNTIF($D$2:$D$2000,G4)=0),"Condition inconnue",IF(G4=D4,"Dépend d'elle-même",IF(J4="","Aucune réf. BPP",IF(AND(B4="Question",M4=""),"Sévérité manquante","OK")))))) | L4: =", "&J4&"," | M4: Majeur | N4: Exigence générale de qualité constante des préparations
A5: 4 | B5: Question | D5: Q002 | E5: Q001 | I5: Il existe un Système d'Assurance Qualité | J5: 1.02 | K5: =IF(COUNTIF($D$2:$D$2000,D5)>1,"Code en double",IF(AND(F5<>"",COUNTIF($D$2:$D$2000,F5)=0),"Question chapeau inconnue",IF(AND(G5<>"",COUNTIF($D$2:$D$2000,G5)=0),"Condition inconnue",IF(G5=D5,"Dépend d'elle-même",IF(J5="","Aucune réf. BPP",IF(AND(B5="Question",M5=""),"Sévérité manquante","OK")))))) | L5: =", "&J5&"," | M5: Majeur | N5: Absence de système qualité compromet toute la maîtrise
A6: 5 | B6: Question | D6: Q003 | E6: Q002 | G6: Q002 | H6: OUI | I6: Ce système est documenté (MAQ, Procédures, Modes Opératoires, Enregistrements ...) | J6: 1.02 | K6: =IF(COUNTIF($D$2:$D$2000,D6)>1,"Code en double",IF(AND(F6<>"",COUNTIF($D$2:$D$2000,F6)=0),"Question chapeau inconnue",IF(AND(G6<>"",COUNTIF($D$2:$D$2000,G6)=0),"Condition inconnue",IF(G6=D6,"Dépend d'elle-même",IF(J6="","Aucune réf. BPP",IF(AND(B6="Question",M6=""),"Sévérité manquante","OK")))))) | L6: =", "&J6&"," | M6: Majeur | N6: Système qualité non documenté, pratiques non maîtrisées
A7: 6 | B7: Question | D7: Q004 | E7: Q003 | G7: Q002 | H7: OUI | I7: Ce système est controlé (auto-inspection, audits,..) | J7: 1.02, 1.05 | K7: =IF(COUNTIF($D$2:$D$2000,D7)>1,"Code en double",IF(AND(F7<>"",COUNTIF($D$2:$D$2000,F7)=0),"Question chapeau inconnue",IF(AND(G7<>"",COUNTIF($D$2:$D$2000,G7)=0),"Condition inconnue",IF(G7=D7,"Dépend d'elle-même",IF(J7="","Aucune réf. BPP",IF(AND(B7="Question",M7=""),"Sévérité manquante","OK")))))) | L7: =", "&J7&"," | M7: Majeur | N7: Absence d'audits empêche détection des dérives
A8: 7 | B8: Question | D8: Q005 | E8: Q004 | G8: Q002 | H8: OUI | I8: Des indicateurs qualités sont identifiés et suivis | J8: 1.02, 1.05 | K8: =IF(COUNTIF($D$2:$D$2000,D8)>1,"Code en double",IF(AND(F8<>"",COUNTIF($D$2:$D$2000,F8)=0),"Question chapeau inconnue",IF(AND(G8<>"",COUNTIF($D$2:$D$2000,G8)=0),"Condition inconnue",IF(G8=D8,"Dépend d'elle-même",IF(J8="","Aucune réf. BPP",IF(AND(B8="Question",M8=""),"Sévérité manquante","OK")))))) | L8: =", "&J8&"," | M8: Mineur | N8: Indicateurs qualité : outil de pilotage
A9: 8 | B9: Titre | C9: 2 | I9: SYSTÈME QUALITÉ PHARMACEUTIQUE
A10: 9 | B10: Question | D10: Q006 | E10: Q005 | G10: Q002 | H10: OUI | I10: Le Système d'Assurance Qualité est basé sur les "Bonnes Pratiques de Préparation" publiées par l'ANSM en 2023 (documents qualités intégrant les BPP) | J10: 1.03, 1.04, 1.06, 1.07, 1.02 | K10: =IF(COUNTIF($D$2:$D$2000,D10)>1,"Code en double",IF(AND(F10<>"",COUNTIF($D$2:$D$2000,F10)=0),"Question chapeau inconnue",IF(AND(G10<>"",COUNTIF($D$2:$D$2000,G10)=0),"Condition inconnue",IF(G10=D10,"Dépend d'elle-même",IF(J10="","Aucune réf. BPP",IF(AND(B10="Question",M10=""),"Sévérité manquante","OK")))))) | L10: =", "&J10&"," | M10: Mineur | N10: Référence documentaire aux BPP 2023
A11: 10 | B11: Question | D11: Q007 | E11: Q006 | I11: Il existe un Système de Gestion Documentaire | J11: 1.05 | K11: =IF(COUNTIF($D$2:$D$2000,D11)>1,"Code en double",IF(AND(F11<>"",COUNTIF($D$2:$D$2000,F11)=0),"Question chapeau inconnue",IF(AND(G11<>"",COUNTIF($D$2:$D$2000,G11)=0),"Condition inconnue",IF(G11=D11,"Dépend d'elle-même",IF(J11="","Aucune réf. BPP",IF(AND(B11="Question",M11=""),"Sévérité manquante","OK")))))) | L11: =", "&J11&"," | M11: Majeur | N11: Gestion documentaire indispensable à la maîtrise du système
A12: 11 | B12: Question | D12: Q008 | E12: Q007 | G12: Q002 | H12: OUI | I12: Le système d'assurance qualité est connu du personnel impliqué dans la production | J12: 1.05 | K12: =IF(COUNTIF($D$2:$D$2000,D12)>1,"Code en double",IF(AND(F12<>"",COUNTIF($D$2:$D$2000,F12)=0),"Question chapeau inconnue",IF(AND(G12<>"",COUNTIF($D$2:$D$2000,G12)=0),"Condition inconnue",IF(G12=D12,"Dépend d'elle-même",IF(J12="","Aucune réf. BPP",IF(AND(B12="Question",M12=""),"Sévérité manquante","OK")))))) | L12: =", "&J12&"," | M12: Majeur | N12: Personnel ignorant le système qualité
A13: 12 | B13: Question | D13: Q009 | E13: Q008 | I13: Les préparations pharmaceutiques sont formulées et réalisées selon l’état des connaissances scientifiques, médicales et pharmaceutiques et l'analyse y conduisant est tracée (exemple de dossier de préparation suivant annexe) | J13: 1.05 | K13: =IF(COUNTIF($D$2:$D$2000,D13)>1,"Code en double",IF(AND(F13<>"",COUNTIF($D$2:$D$2000,F13)=0),"Question chapeau inconnue",IF(AND(G13<>"",COUNTIF($D$2:$D$2000,G13)=0),"Condition inconnue",IF(G13=D13,"Dépend d'elle-même",IF(J13="","Aucune réf. BPP",IF(AND(B13="Question",M13=""),"Sévérité manquante","OK")))))) | L13: =", "&J13&"," | M13: Majeur | N13: Formulation non justifiée scientifiquement, traçabilité de l'analyse
A14: 13 | B14: Titre | C14: 2 | I14: BONNES PRATIQUES DE PRÉPARATION
A15: 14 | B15: Titre | C15: 2 | I15: REVUE QUALITÉ DES PRÉPARATIONS PHARMACEUTIQUES
A16: 15 | B16: Question | D16: Q010 | E16: Q009 | I16: Des revues qualité sont organisées selon une périodicité définie après analyse des réclamations et des non-conformité | J16: 1.10 | K16: =IF(COUNTIF($D$2:$D$2000,D16)>1,"Code en double",IF(AND(F16<>"",COUNTIF($D$2:$D$2000,F16)=0),"Question chapeau inconnue",IF(AND(G16<>"",COUNTIF($D$2:$D$2000,G16)=0),"Condition inconnue",IF(G16=D16,"Dépend d'elle-même",IF(J16="","Aucune réf. BPP",IF(AND(B16="Question",M16=""),"Sévérité manquante","OK")))))) | L16: =", "&J16&"," | M16: Mineur | N16: Revue qualité périodique
A17: 16 | B17: Question | D17: Q011 | E17: Q010 | G17: Q010 | H17: OUI | I17: Les revues qualités sont documentées | J17: 1.10 | K17: =IF(COUNTIF($D$2:$D$2000,D17)>1,"Code en double",IF(AND(F17<>"",COUNTIF($D$2:$D$2000,F17)=0),"Question chapeau inconnue",IF(AND(G17<>"",COUNTIF($D$2:$D$2000,G17)=0),"Condition inconnue",IF(G17=D17,"Dépend d'elle-même",IF(J17="","Aucune réf. BPP",IF(AND(B17="Question",M17=""),"Sévérité manquante","OK")))))) | L17: =", "&J17&"," | M17: Mineur | N17: Documentation des revues qualité
A18: 17 | B18: Question | D18: Q012 | E18: Q011 | G18: Q010 | H18: OUI | I18: Les revues qualités alimentent l'analyse globale de risque | J18: 1.10 | K18: =IF(COUNTIF($D$2:$D$2000,D18)>1,"Code en double",IF(AND(F18<>"",COUNTIF($D$2:$D$2000,F18)=0),"Question chapeau inconnue",IF(AND(G18<>"",COUNTIF($D$2:$D$2000,G18)=0),"Condition inconnue",IF(G18=D18,"Dépend d'elle-même",IF(J18="","Aucune réf. BPP",IF(AND(B18="Question",M18=""),"Sévérité manquante","OK")))))) | L18: =", "&J18&"," | M18: Mineur | N18: Lien revues qualité et analyse de risque
A19: 18 | B19: Titre | C19: 2 | I19: APPRÉCIATION DU RISQUE DE LA PRÉPARATION PHARMACEUTIQUE
A20: 19 | B20: Question | D20: Q013 | E20: Q012 | I20: L'appréciation du risque de la préparation pharmaceutique est réalisée (bénéfice/risque), permettant de décider si des mesures de réduction du risque doivent être mises en œuvre, ou si le risque existant peut être accepté | J20: 1.11 | K20: =IF(COUNTIF($D$2:$D$2000,D20)>1,"Code en double",IF(AND(F20<>"",COUNTIF($D$2:$D$2000,F20)=0),"Question chapeau inconnue",IF(AND(G20<>"",COUNTIF($D$2:$D$2000,G20)=0),"Condition inconnue",IF(G20=D20,"Dépend d'elle-même",IF(J20="","Aucune réf. BPP",IF(AND(B20="Question",M20=""),"Sévérité manquante","OK")))))) | L20: =", "&J20&"," | M20: Majeur | N20: Appréciation bénéfice/risque de la préparation
A21: 20 | B21: Question | D21: Q014 | E21: Q013 | I21: Une analyse pharmaceutique et réglementaire est réalisée pour chaque type de préparation (annexe I) | J21: 1.12 | K21: =IF(COUNTIF($D$2:$D$2000,D21)>1,"Code en double",IF(AND(F21<>"",COUNTIF($D$2:$D$2000,F21)=0),"Question chapeau inconnue",IF(AND(G21<>"",COUNTIF($D$2:$D$2000,G21)=0),"Condition inconnue",IF(G21=D21,"Dépend d'elle-même",IF(J21="","Aucune réf. BPP",IF(AND(B21="Question",M21=""),"Sévérité manquante","OK")))))) | L21: =", "&J21&"," | M21: Majeur | N21: Analyse pharmaceutique et réglementaire par type de préparation
A22: 21 | B22: Question | D22: Q015 | E22: Q014 | G22: Q014 | H22: OUI | I22: L'analyse pharmaceutique et réglementaire pour chaque type de préparation (annexe I) est réalisée et en cas de refus un critère explicite est tracé pour justifier la non réalisation | J22: 1.20 | K22: =IF(COUNTIF($D$2:$D$2000,D22)>1,"Code en double",IF(AND(F22<>"",COUNTIF($D$2:$D$2000,F22)=0),"Question chapeau inconnue",IF(AND(G22<>"",COUNTIF($D$2:$D$2000,G22)=0),"Condition inconnue",IF(G22=D22,"Dépend d'elle-même",IF(J22="","Aucune réf. BPP",IF(AND(B22="Question",M22=""),"Sévérité manquante","OK")))))) | L22: =", "&J22&"," | M22: Mineur | N22: Traçabilité du motif de refus
A23: 22 | B23: Question | D23: Q016 | E23: Q015 | I23: En cas d’impossibilité de réalisation de préparation, un contrat de sous-traitance est établi en amont, selon les modalités décrites par par le présent texte. | J23: 1.19 | K23: =IF(COUNTIF($D$2:$D$2000,D23)>1,"Code en double",IF(AND(F23<>"",COUNTIF($D$2:$D$2000,F23)=0),"Question chapeau inconnue",IF(AND(G23<>"",COUNTIF($D$2:$D$2000,G23)=0),"Condition inconnue",IF(G23=D23,"Dépend d'elle-même",IF(J23="","Aucune réf. BPP",IF(AND(B23="Question",M23=""),"Sévérité manquante","OK")))))) | L23: =", "&J23&"," | M23: Majeur | N23: Contrat de sous-traitance préalable
A24: 23 | B24: Question | D24: Q017 | E24: Q016 | I24: En cas d’impossibilité de réalisation d'une préparation, la notification et/ou proposition d'alternative au prescripteur est tracée | J24: 1.21 | K24: =IF(COUNTIF($D$2:$D$2000,D24)>1,"Code en double",IF(AND(F24<>"",COUNTIF($D$2:$D$2000,F24)=0),"Question chapeau inconnue",IF(AND(G24<>"",COUNTIF($D$2:$D$2000,G24)=0),"Condition inconnue",IF(G24=D24,"Dépend d'elle-même",IF(J24="","Aucune réf. BPP",IF(AND(B24="Question",M24=""),"Sévérité manquante","OK")))))) | L24: =", "&J24&"," | M24: Mineur | N24: Traçabilité de la notification au prescripteur
A25: 24 | B25: Question | D25: Q018 | E25: Q017 | I25: Une analyse de risque simplifiée est réalisée pour les préparations demandées en urgence | J25: 1.22 | K25: =IF(COUNTIF($D$2:$D$2000,D25)>1,"Code en double",IF(AND(F25<>"",COUNTIF($D$2:$D$2000,F25)=0),"Question chapeau inconnue",IF(AND(G25<>"",COUNTIF($D$2:$D$2000,G25)=0),"Condition inconnue",IF(G25=D25,"Dépend d'elle-même",IF(J25="","Aucune réf. BPP",IF(AND(B25="Question",M25=""),"Sévérité manquante","OK")))))) | L25: =", "&J25&"," | M25: Majeur | N25: Analyse de risque des préparations urgentes
A26: 25 | B26: Question | D26: Q019 | E26: Q018 | G26: Q014 | H26: OUI | I26: L'analyse technico-réglementaire des préparations est réalisée (annexe II partie 1) avant toute décision de réalisation | J26: 1.13, 1.15, 5.41 | K26: =IF(COUNTIF($D$2:$D$2000,D26)>1,"Code en double",IF(AND(F26<>"",COUNTIF($D$2:$D$2000,F26)=0),"Question chapeau inconnue",IF(AND(G26<>"",COUNTIF($D$2:$D$2000,G26)=0),"Condition inconnue",IF(G26=D26,"Dépend d'elle-même",IF(J26="","Aucune réf. BPP",IF(AND(B26="Question",M26=""),"Sévérité manquante","OK")))))) | L26: =", "&J26&"," | M26: Majeur | N26: Analyse technico-réglementaire avant réalisation
A27: 26 | B27: Question | D27: Q020 | E27: Q019 | G27: Q014 | H27: OUI | I27: L'analyse technico-réglementaire des préparations prend en compte la réglementation en vigueur (interdictions, restrictions, Formulaire National…) | J27: 1.17 | K27: =IF(COUNTIF($D$2:$D$2000,D27)>1,"Code en double",IF(AND(F27<>"",COUNTIF($D$2:$D$2000,F27)=0),"Question chapeau inconnue",IF(AND(G27<>"",COUNTIF($D$2:$D$2000,G27)=0),"Condition inconnue",IF(G27=D27,"Dépend d'elle-même",IF(J27="","Aucune réf. BPP",IF(AND(B27="Question",M27=""),"Sévérité manquante","OK")))))) | L27: =", "&J27&"," | M27: Majeur | N27: Prise en compte des interdictions réglementaires
A28: 27 | B28: Question | D28: Q021 | E28: Q020 | I28: Des analyses de risques concernant l'intégralité du processus de préparation sont réalisées (annexe III) | J28: 1.11, 4.05, 5.13, 5.23 | K28: =IF(COUNTIF($D$2:$D$2000,D28)>1,"Code en double",IF(AND(F28<>"",COUNTIF($D$2:$D$2000,F28)=0),"Question chapeau inconnue",IF(AND(G28<>"",COUNTIF($D$2:$D$2000,G28)=0),"Condition inconnue",IF(G28=D28,"Dépend d'elle-même",IF(J28="","Aucune réf. BPP",IF(AND(B28="Question",M28=""),"Sévérité manquante","OK")))))) | L28: =", "&J28&"," | M28: Majeur | N28: Analyse de risque du processus de préparation
A29: 28 | B29: Question | D29: Q022 | E29: Q021 | I29: Une analyse de risque est réalisée pour classer la préparation en risque faible, moyen ou élevé, selon les critères de l'annexe III (substance active, voie d'administration, forme pharmaceutique, opérations réalisées, nombre de patients), permettant de la classer en risque faible, moyen ou élevé | J29: 1.16, 5.23 | K29: =IF(COUNTIF($D$2:$D$2000,D29)>1,"Code en double",IF(AND(F29<>"",COUNTIF($D$2:$D$2000,F29)=0),"Question chapeau inconnue",IF(AND(G29<>"",COUNTIF($D$2:$D$2000,G29)=0),"Condition inconnue",IF(G29=D29,"Dépend d'elle-même",IF(J29="","Aucune réf. BPP",IF(AND(B29="Question",M29=""),"Sévérité manquante","OK")))))) | L29: =", "&J29&"," | M29: Majeur | N29: Classement du niveau de risque de la préparation
A30: 29 | B30: Question | D30: Q023 | E30: Q022 | G30: Q022 | H30: OUI | I30: Dans le cadre de l'analyse de risque pour classer la préparation, le niveau de risque « produit » (contamination microbiologique pour le patient) et le niveau de risque « personnel/environnement » (toxicité, CMR, produits biologiques/OGM) sont identifiés et distingués pour chaque produit. | J30: LD1.026 | K30: =IF(COUNTIF($D$2:$D$2000,D30)>1,"Code en double",IF(AND(F30<>"",COUNTIF($D$2:$D$2000,F30)=0),"Question chapeau inconnue",IF(AND(G30<>"",COUNTIF($D$2:$D$2000,G30)=0),"Condition inconnue",IF(G30=D30,"Dépend d'elle-même",IF(J30="","Aucune réf. BPP",IF(AND(B30="Question",M30=""),"Sévérité manquante","OK")))))) | L30: =", "&J30&"," | M30: Majeur | N30: Distinction risque produit et risque personnel
A31: 30 | B31: Question | D31: Q024 | E31: Q023 | I31: Une analyse de risque toxicologique de la préparation est réalisée, appuyée sur une recherche bibliographique sur les substances actives et excipients | J31: 4.32 | K31: =IF(COUNTIF($D$2:$D$2000,D31)>1,"Code en double",IF(AND(F31<>"",COUNTIF($D$2:$D$2000,F31)=0),"Question chapeau inconnue",IF(AND(G31<>"",COUNTIF($D$2:$D$2000,G31)=0),"Condition inconnue",IF(G31=D31,"Dépend d'elle-même",IF(J31="","Aucune réf. BPP",IF(AND(B31="Question",M31=""),"Sévérité manquante","OK")))))) | L31: =", "&J31&"," | M31: Majeur | N31: Analyse toxicologique des substances et excipients
A32: 31 | B32: Question | D32: Q025 | E32: Q024 | I32: Une analyse de risque relative à la réattribution des préparations est réalisée | J32: 5.61, 5.63 | K32: =IF(COUNTIF($D$2:$D$2000,D32)>1,"Code en double",IF(AND(F32<>"",COUNTIF($D$2:$D$2000,F32)=0),"Question chapeau inconnue",IF(AND(G32<>"",COUNTIF($D$2:$D$2000,G32)=0),"Condition inconnue",IF(G32=D32,"Dépend d'elle-même",IF(J32="","Aucune réf. BPP",IF(AND(B32="Question",M32=""),"Sévérité manquante","OK")))))) | L32: =", "&J32&"," | M32: Majeur | N32: Analyse de risque de la réattribution
A33: 32 | B33: Question | D33: Q026 | E33: Q025 | G33: Q022 | H33: OUI | I33: Le niveau de contrôle qualité appliqué est justifié par référence à l'analyse de risque réalisée pour chaque préparation de la préparation (cf. art. 1.16) | J33: 6.59 | K33: =IF(COUNTIF($D$2:$D$2000,D33)>1,"Code en double",IF(AND(F33<>"",COUNTIF($D$2:$D$2000,F33)=0),"Question chapeau inconnue",IF(AND(G33<>"",COUNTIF($D$2:$D$2000,G33)=0),"Condition inconnue",IF(G33=D33,"Dépend d'elle-même",IF(J33="","Aucune réf. BPP",IF(AND(B33="Question",M33=""),"Sévérité manquante","OK")))))) | L33: =", "&J33&"," | M33: Majeur | N33: Niveau de contrôle justifié par analyse de risque
A34: 33 | B34: Question | D34: Q027 | E34: Q026 | I34: Une analyse du risque d'interactions contenant-contenu est conduite (excipients à risque, données littérature/fournisseur/internes), avec recherche documentée de l'absence d'interaction. | J34: 6.85 | K34: =IF(COUNTIF($D$2:$D$2000,D34)>1,"Code en double",IF(AND(F34<>"",COUNTIF($D$2:$D$2000,F34)=0),"Question chapeau inconnue",IF(AND(G34<>"",COUNTIF($D$2:$D$2000,G34)=0),"Condition inconnue",IF(G34=D34,"Dépend d'elle-même",IF(J34="","Aucune réf. BPP",IF(AND(B34="Question",M34=""),"Sévérité manquante","OK")))))) | L34: =", "&J34&"," | M34: Majeur | N34: Analyse des interactions contenant-contenu
A35: 34 | B35: Question | D35: Q028 | E35: Q027 | I35: Une analyse de risque est réalisée pour la conception et de l’aménagement des locaux (matière première utilisée /procédé utilisé) | J35: 3.19, 5.18, 5.19, 5.20, 5.21, 5.22 | K35: =IF(COUNTIF($D$2:$D$2000,D35)>1,"Code en double",IF(AND(F35<>"",COUNTIF($D$2:$D$2000,F35)=0),"Question chapeau inconnue",IF(AND(G35<>"",COUNTIF($D$2:$D$2000,G35)=0),"Condition inconnue",IF(G35=D35,"Dépend d'elle-même",IF(J35="","Aucune réf. BPP",IF(AND(B35="Question",M35=""),"Sévérité manquante","OK")))))) | L35: =", "&J35&"," | M35: Majeur | N35: Analyse de risque pour la conception des locaux
A36: 35 | B36: Question | D36: Q029 | E36: Q028 | I36: Une analyse de risque documentée justifie le d'une choix zone (plutôt que local dédié) pour les catégories 1-3 non stériles/non CMR | J36: 3.15 | K36: =IF(COUNTIF($D$2:$D$2000,D36)>1,"Code en double",IF(AND(F36<>"",COUNTIF($D$2:$D$2000,F36)=0),"Question chapeau inconnue",IF(AND(G36<>"",COUNTIF($D$2:$D$2000,G36)=0),"Condition inconnue",IF(G36=D36,"Dépend d'elle-même",IF(J36="","Aucune réf. BPP",IF(AND(B36="Question",M36=""),"Sévérité manquante","OK")))))) | L36: =", "&J36&"," | M36: Mineur | N36: Justification documentée zone versus local dédié
A37: 36 | B37: Question | D37: Q030 | E37: Q029 | I37: La stratégie de libération repose sur une évaluation du risque formalisée et documentée. | J37: 6.70 | K37: =IF(COUNTIF($D$2:$D$2000,D37)>1,"Code en double",IF(AND(F37<>"",COUNTIF($D$2:$D$2000,F37)=0),"Question chapeau inconnue",IF(AND(G37<>"",COUNTIF($D$2:$D$2000,G37)=0),"Condition inconnue",IF(G37=D37,"Dépend d'elle-même",IF(J37="","Aucune réf. BPP",IF(AND(B37="Question",M37=""),"Sévérité manquante","OK")))))) | L37: =", "&J37&"," | M37: Majeur | N37: Stratégie de libération fondée sur le risque
A38: 37 | B38: Question | D38: Q031 | E38: Q030 | I38: Une analyse de risque préalable et documentée est réalisée pour le choix des installations et des équipements de préparation stérile | J38: LD1.034, 5.18, 5.19, 5.20, 5.21, 5.22 | K38: =IF(COUNTIF($D$2:$D$2000,D38)>1,"Code en double",IF(AND(F38<>"",COUNTIF($D$2:$D$2000,F38)=0),"Question chapeau inconnue",IF(AND(G38<>"",COUNTIF($D$2:$D$2000,G38)=0),"Condition inconnue",IF(G38=D38,"Dépend d'elle-même",IF(J38="","Aucune réf. BPP",IF(AND(B38="Question",M38=""),"Sévérité manquante","OK")))))) | L38: =", "&J38&"," | M38: Majeur | N38: Analyse de risque choix équipements stériles
A39: 38 | B39: Question | D39: Q032 | E39: Q031 | G39: Q031 | H39: OUI | I39: L'analyse de risque pour le choix des équipement et l'environnement se base sur les niveaux de risque produit et de la nature des manipulations | J39: LD1.027, LD1.028, LD1.029, LD1.030, LD1.031 | K39: =IF(COUNTIF($D$2:$D$2000,D39)>1,"Code en double",IF(AND(F39<>"",COUNTIF($D$2:$D$2000,F39)=0),"Question chapeau inconnue",IF(AND(G39<>"",COUNTIF($D$2:$D$2000,G39)=0),"Condition inconnue",IF(G39=D39,"Dépend d'elle-même",IF(J39="","Aucune réf. BPP",IF(AND(B39="Question",M39=""),"Sévérité manquante","OK")))))) | L39: =", "&J39&"," | M39: Majeur | N39: Critères de l'analyse de risque équipements
A40: 39 | B40: Question | D40: Q033 | E40: Q032 | I40: Une analyse de risque préalable est réalisée pour le procédé de stérilisation de contact à l'intérieur de l'isolateur | J40: LD1.076 | K40: =IF(COUNTIF($D$2:$D$2000,D40)>1,"Code en double",IF(AND(F40<>"",COUNTIF($D$2:$D$2000,F40)=0),"Question chapeau inconnue",IF(AND(G40<>"",COUNTIF($D$2:$D$2000,G40)=0),"Condition inconnue",IF(G40=D40,"Dépend d'elle-même",IF(J40="","Aucune réf. BPP",IF(AND(B40="Question",M40=""),"Sévérité manquante","OK")))))) | L40: =", "&J40&"," | M40: Majeur | N40: Analyse de risque stérilisation de contact isolateur
...

Sheet Sévérités
A1: Répartition des sévérités
A3: Niveau | B3: Nombre de questions
A4: Critique | B4: =COUNTIF('Référentiel'!$M:$M,A4)
A5: Majeur | B5: =COUNTIF('Référentiel'!$M:$M,A5)
A6: Mineur | B6: =COUNTIF('Référentiel'!$M:$M,A6)
A7: Total | B7: =SUM(B4:B6)
A9: Pondération appliquée selon la réponse (dans l'outil questionnaire)
A11: Réponse | B11: Poids | C11: Justification
A12: Conforme | B12: 0 | C12: Confirmé conforme : aucun risque retenu.
A13: Partiellement conforme | B13: 0.5 | C13: Écart confirmé mais partiel.
A14: Non applicable | B14: 0 | C14: Neutre, comme Conforme : ne contribue pas au verdict de risque.
A15: Non conforme | B15: 1 | C15: Écart confirmé et total : poids plein.
A17: Verdict d'un chapitre = sévérité la plus élevée parmi les écarts pondérés (poids > 0) qu'il contient. Un seul écart Critique confirmé (Non conforme, poids 1) suffit à classer tout le chapitre en risque critique ; un écart Critique seulement partiel (poids 0,5) le fait basculer en risque majeur, un écart Majeur partiel en risque mineur. Le Non applicable n'a pas d'effet sur ce calcul. Lorsqu'une question maître est répondue « Non » (ou « N/A »), les questions qui en dépendent sont réputées « Non » (ou « N/A »).

Sheet Références BPP
A1: Réf. BPP | B1: Texte officiel | C1: Nb de questions
A2: 1.01 | B2: Afin de protéger la santé humaine, les préparations pharmaceutiques sont réalisées de façon à garantir une qualité constante, appropriée à leur usage. Pour atteindre cet objectif elles sont réalisées en conformité avec les exigences définies dans le présent texte. | C2: =COUNTIF(Référentiel!$L$2:$L$1371,"*, "&A2&",*")
A3: 1.02 | B3: Les pharmacies à usage intérieur et les pharmacies d'officine disposent d’un système d’assurance qualité qui intègre l’ensemble des règles de bonnes pratiques présentées dans ce texte. Ce système est documenté et contrôlé et son efficacité est surveillée. | C3: =COUNTIF(Référentiel!$L$2:$L$1371,"*, "&A3&",*")
A4: 1.03 | B4: Les concepts fondamentaux de la gestion de la qualité, des Bonnes Pratiques de Préparation (BPP) et de la gestion du risque sont étroitement liés. Ils sont décrits ci-après en vue de souligner leurs relations réciproques et leur importance fondamentale dans la production et le contrôle des préparations pharmaceutiques. | C4: =COUNTIF(Référentiel!$L$2:$L$1371,"*, "&A4&",*")
A5: 1.04 | B5: La gestion de la qualité est un concept large qui couvre tout ce qui peut, individuellement ou collectivement, avoir une influence sur la qualité d’un produit. Elle représente l’ensemble des dispositions prises pour garantir que les préparations sont conformes aux spécifications attendues et de qualité requise pour l’usage auquel elles sont destinées. La gestion de la qualité intègre les BPP. | C5: =COUNTIF(Référentiel!$L$2:$L$1371,"*, "&A5&",*")
A6: 1.05 | B6: Le système d’assurance qualité est soumis à une évaluation de son efficacité et de son adéquation entre le présent texte et les pratiques mises en oeuvre : -un système documentaire est mis en place et maîtrisé ; -les préparations sont formulées et réalisées selon l’état des connaissances scientifiques, médicales et pharmaceutiques ; -les procédés de préparation et de contrôle sont clairement décrits et les règles figurant dans le présent texte sont appliquées ; -une fois réalisées, les préparations n’entrent dans le circuit de dispensation qu’une fois contrôlées et libérées conformément aux procédures établies ; -des dispositions sont prises pour garantir la qualité des préparations jusqu’à leur date de péremption et leur délai limite d’utilisation après ouverture. | C6: =COUNTIF(Référentiel!$L$2:$L$1371,"*, "&A6&",*")
A7: 1.06 | B7: Les BPP constituent un des éléments de la gestion de la qualité qui garantit que les préparations pharmaceutiques sont réalisées et contrôlées de façon cohérente, selon leurs spécifications et les normes de qualité adaptées à leur usage. | C7: =COUNTIF(Référentiel!$L$2:$L$1371,"*, "&A7&",*")
A8: 1.07 | B8: Les BPP s’appliquent à la fois à la production et au contrôle de la qualité des préparations pharmaceutiques. Les exigences fondamentales des BPP sont les suivantes : -le personnel est qualifié et formé à la fonction qu’il occupe. Les responsabilités et les compétences sont clairement définies ; -les locaux et équipements sont adaptés aux préparations à réaliser ; -tous les facteurs influençant la qualité des préparations sont évalués et sont décrits dans des documents appropriés ; -tout procédé de préparation respecte le présent texte. Toutes les étapes requises par les procédures sont documentées. Les dossiers de lot sont établis de manière à permettre la traçabilité complète du lot de la préparation concernée jusqu’à sa libération et sa dispensation aux patients, en tenant compte des dispositions décrites au chapitre 7 dans le cas où l’activité est externalisée ; -la manipulation, le transport et le stockage des matières premières à usage pharmaceutique (MPUP) et des articles de conditionnement se déroulent de façon à garantir leur qualité pendant toute leur durée de validité ; -la qualité des produits obtenus est évaluée et satisfait aux exigences requises ; l’évaluation est documentée et inclut : *un examen des documents de préparation ; *la réalisation de contrôles qualité ; * une comparaison entre les résultats des contrôles qualité et les spécifications exigées ; *une analyse des écarts éventuels. -les lots ne sont libérés qu’après vérification et attestation de leur conformité aux spécifications requises ; -les réclamations et les non-conformités concernant les préparations pharmaceutiques, les MPUP et les articles de conditionnement sont examinées et étudiées afin de prendre les mesures correctives adaptées. | C8: =COUNTIF(Référentiel!$L$2:$L$1371,"*, "&A8&",*")
A9: 1.08 | B9: Le contrôle de la qualité fait partie des BPP (cf. Chapitre 6). Il concerne l’échantillonnage, les spécifications et le contrôle, ainsi que les procédures d’organisation, de documentation et de libération qui garantissent que les contrôles qualité nécessaires et appropriés sont réellement effectués. Les MPUP, les articles de conditionnement, les produits intermédiaires, les préparations utilisées pour la réalisation d’autres préparations et les préparations terminées ne sont libérées qu’après vérification de leur qualité et de leur conformité aux spécifications. | C9: =COUNTIF(Référentiel!$L$2:$L$1371,"*, "&A9&",*")
A10: 1.09 | B10: La nature du contrôle de la qualité est définie et justifiée en fonction de l'analyse de risque réalisée pour la préparation concernée. | C10: =COUNTIF(Référentiel!$L$2:$L$1371,"*, "&A10&",*")
A11: 1.10 | B11: Après analyse des réclamations et des non-conformités, il est recommandé de réaliser des revues qualités portant notamment sur les préparations pour lesquelles un écart ou une modification substantielle a été relevée. Ces revues sont menées afin de vérifier la répétabilité des procédés existants, la pertinence des spécifications initialement décrites dans le dossier de préparation (cf. Annexe II) pour les MPUP, les articles de conditionnement, les produits intermédiaires et les préparations terminées. Ces revues permettent de mettre en évidence toute évolution et d’identifier les améliorations à apporter aux produits et aux procédés. Elles alimentent l’analyse globale du risque lié à la préparation et sont normalement menées et documentées selon une périodicité appropriée et justifiée. Elles prennent en compte les revues précédentes. Elles comprennent notamment le suivi des éléments suivants : -Les MPUP et les articles de conditionnement utilisés pour la préparation, notamment ceux provenant de nouvelles sources d’approvisionnement, ainsi que la traçabilité de la chaîne d’approvisionnement des substances actives ; -les résultats des contrôles qualité des préparations terminées ; -les lots non conformes aux spécifications établies ainsi que les investigations correspondantes ; -les déviations significatives et les non-conformités, les investigations correspondantes et l'efficacité des actions correctives et préventives prises en conséquence ; -les modifications intervenues sur les procédés ou sur les méthodes d'analyse ; -les retours, réclamations et rappels liés à des problèmes de qualité ainsi que les investigations correspondantes ; -la pertinence de toute mesure corrective antérieure relative au procédé de préparation ou aux équipements ; -la qualification des principaux équipements et de leurs utilités, par exemple les installations de traitement de l’air, de production et de distribution de l’eau ou de gaz comprimés ; -les contrats et/ou cahiers des charges et/ou plannings de maintenance technique afin de s'assurer qu'ils sont à jour. | C11: =COUNTIF(Référentiel!$L$2:$L$1371,"*, "&A11&",*")
A12: 1.11 | B12: L’appréciation du rapport bénéfice/risque permet d’évaluer les dangers potentiels et sert de base pour décider si des mesures de réduction des risques sont à appliquer, ou si le risque existant peut être accepté. | C12: =COUNTIF(Référentiel!$L$2:$L$1371,"*, "&A12&",*")
A13: 1.12 | B13: Quel que soit le risque associé à la réalisation d'une préparation et préalablement à sa réalisation, une analyse pharmaceutique est réalisée par le pharmacien qui reçoit la demande. Un exemple d’outil d’aide à l’analyse pharmaceutique et réglementaire est proposé (cf. Annexe I). | C13: =COUNTIF(Référentiel!$L$2:$L$1371,"*, "&A13&",*")
... A599: LD3.28 | B599: Après la destruction des médicaments expérimentaux, un certificat daté ou une attestation confirmant la réalisation de cette opération est remis au promoteur. Ces documents identifient clairement, ou permettent d’assurer la traçabilité des lots et/ou des numéros de traitement et/ou des numéros de personnes incluses dans la RIPH concernée, ainsi que les quantités effectivement détruites. | C599: =COUNTIF(Référentiel!$L$2:$L$1371,"*, "&A599&",*")

Sheet Journal
A1: Date | B1: Code | C1: Modification
A2: 09/10/2026 | C2: Colonnes « Sévérité » (Critique / Majeur / Mineur) et « Motif de la sévérité » ajoutées pour les 1 168 questions ; feuille « Sévérités » (répartition et pondération). Grille proposée, à valider.
A3: 08/10/2026 | C3: Version 2026-10-08 : « S 01 » était une erreur de numérotation ; elle devient Q001 et toutes les questions sont décalées d'un rang (Q001 → Q002 … Q744 → Q745), sous-questions, questions chapeau et conditions comprises.
A4: 08/10/2026 | C4: Colonne « Ancien code » : code de chaque question dans la version 2026-10-07 (les réponses déjà saisies suivent leur question à l'import).
A5: 07/10/2026 | C5: Fichier maître créé à partir de « auto_inspection_BPP_version_jft_07_10_2026_v10.xlsx » (feuille « ordre question »).
A6: 07/10/2026 | C6: Une ligne par élément (au lieu d'une ligne par couple question × référence) ; références regroupées en colonne J.
A7: 07/10/2026 | C7: Niveaux de titres explicités en colonne C (1 = chapitre … 5), repris de la structure validée dans l'outil.
A8: 07/10/2026 | C8: Titres : accents et libellés normalisés (ex. « SYTEME » → « SYSTÈME », « LD1 » → « Préparations stériles - LD1 »).
A9: 07/10/2026 | C9: Questions renumérotées par rapport à la version initiale de l'outil (suppression du trou Q102, fusion Q641/Q642).
A10: 07/10/2026 | B10: Q641 | C10: Fusion des anciennes Q641 et Q642 (intitulé identique, Q640 en version 2026-10-07) ; références LD2.013 rattachées.
A11: 07/10/2026 | C11: Références mal saisies normalisées : 1.7 → 1.07, 5.7 → 5.07, 5.8 → 5.08, 8.1 → 8.01, 8.9 → 8.09, LD1 046 → LD1.046, LD1 116. → LD1.116, LD2.06 → LD2.006, LD2.07 → LD2.007, LD2.034. → LD2.034 (pour 1.7 et 5.8 / LD1.046 / LD1.116, le texte de la forme correcte, déjà présent, est conservé).
A12: 07/10/2026 | B12: Q624.04.01 | C12: Anciennes Q624.05 / Q624.06 (« cytotoxiques », « non cytotoxiques ») rattachées à l'intitulé commun Q623.04.
A13: 07/10/2026 | B13: Q087 | C13: Condition « Q085 » complétée en « Q086-OUI » (réponse attendue explicitée)
A14: 07/10/2026 | B14: Q125 | C14: Condition « Q123 » complétée en « Q124-OUI » (réponse attendue explicitée)
A15: 07/10/2026 | B15: Q126 | C15: Condition « Q123 » complétée en « Q124-OUI » (réponse attendue explicitée)
A16: 07/10/2026 | B16: Q211 | C16: Condition « Q210-OUI » (la question dépendait d'elle-même) remplacée par « Q210-OUI »
A17: 07/10/2026 | B17: Q549.01 | C17: Code « Q548-01 » renuméroté « Q548.01 » (sous-question : séparateur point)
A18: 07/10/2026 | B18: Q549.02 | C18: Code « Q548-02 » renuméroté « Q548.02 » (sous-question : séparateur point)
A19: 07/10/2026 | B19: Q549.03 | C19: Code « Q548-03 » renuméroté « Q548.03 » (sous-question : séparateur point)
A20: 07/10/2026 | B20: Q549.04 | C20: Code « Q548-04 » renuméroté « Q548.04 » (sous-question : séparateur point)
A21: 07/10/2026 | B21: Q549.05 | C21: Code « Q548-05 » renuméroté « Q548.05 » (sous-question : séparateur point)
A22: 07/10/2026 | B22: Q549.06 | C22: Code « Q548-06 » renuméroté « Q548.06 » (sous-question : séparateur point)
A23: 07/10/2026 | B23: Q549.07 | C23: Code « Q548-07 » renuméroté « Q548.07 » (sous-question : séparateur point)
